<?xml version="1.0"?>

<robot name="little_bas">
	<link name="arm_base" >
		<inertial>
			<origin xyz="0 0 0" rpy="0 0 0"/>
			<mass value="0.1"/>
			<inertia ixx="0.01" ixy="0" ixz="0" iyy="0.01" iyz="0" izz="0.01" />
		</inertial>
		<visual>
			<origin xyz="0 0 0" rpy="0 0 0" />
			<geometry>
			<mesh filename="package://bas_description/meshes/arm/arm_base.dae" />
			</geometry>
			<material name="Black" />
		</visual>
		<collision>
			<origin xyz="0 0 0" rpy="0 0 0" />
			<geometry>
			<mesh filename="package://bas_description/meshes/arm/arm_base.dae" />
			</geometry>
		</collision>
	</link>
	
	<link name="arm_link1" >
		<inertial>
			<origin xyz="0 0 0" rpy="0 0 0"/>
			<mass value="0.1"/>
			<inertia ixx="0.01" ixy="0" ixz="0" iyy="0.01" iyz="0" izz="0.01" />
		</inertial>
		<visual>
			<origin xyz="0 0 0" rpy="0 0 0" />
			<geometry>
			<mesh filename="package://bas_description/meshes/arm/arm_link1.dae" />
			</geometry>
			<material name="Black" />
		</visual>
		<collision>
			<origin xyz="0 0 0" rpy="0 0 0" />
			<geometry>
			<mesh filename="package://bas_description/meshes/arm/arm_link1.dae" />
			</geometry>
		</collision>
	</link>
	
	<link name="arm_link2" >
		<inertial>
			<origin xyz="0 0 0" rpy="0 0 0"/>
			<mass value="0.1"/>
			<inertia ixx="0.01" ixy="0" ixz="0" iyy="0.01" iyz="0" izz="0.01" />
		</inertial>
		<visual>
			<origin xyz="0 0 0" rpy="0 0 0" />
			<geometry>
			<mesh filename="package://bas_description/meshes/arm/arm_link2.dae" />
			</geometry>
			<material name="Black" />
		</visual>
		<collision>
			<origin xyz="0 0 0" rpy="0 0 0" />
			<geometry>
			<mesh filename="package://bas_description/meshes/arm/arm_link2.dae" />
			</geometry>
		</collision>
	</link>

	<joint name="arm_link1" type="continuous">
		<parent link="arm_base"/>
		<child link="arm_link1"/>
		<origin xyz="0 0 0" rpy="0 0 0" />
		<axis xyz="0 0 1" />
	</joint>

	<joint name="arm_link2" type="continuous">
		<parent link="arm_link1"/>
		<child link="arm_link2"/>
		<!--origin xyz="0 0 0" rpy="0 0 0" /-->
		<origin xyz="-2 0 0" rpy="0 0 0" />
		<!--axis xyz="1 0 0" /-->
		<!--axis xyz="0 1 0" /-->
		<axis xyz="0 0 1" />
	</joint>

</robot>